[2022-02-08 01:35:01,163] {taskinstance.py:1032} INFO - Dependencies all met for <TaskInstance: Sample_one.save_csv manual__2022-02-08T01:34:54.618638+00:00 [queued]>
[2022-02-08 01:35:01,174] {taskinstance.py:1032} INFO - Dependencies all met for <TaskInstance: Sample_one.save_csv manual__2022-02-08T01:34:54.618638+00:00 [queued]>
[2022-02-08 01:35:01,175] {taskinstance.py:1238} INFO - 
--------------------------------------------------------------------------------
[2022-02-08 01:35:01,176] {taskinstance.py:1239} INFO - Starting attempt 1 of 1
[2022-02-08 01:35:01,177] {taskinstance.py:1240} INFO - 
--------------------------------------------------------------------------------
[2022-02-08 01:35:01,191] {taskinstance.py:1259} INFO - Executing <Task(BashOperator): save_csv> on 2022-02-08 01:34:54.618638+00:00
[2022-02-08 01:35:01,199] {standard_task_runner.py:52} INFO - Started process 801 to run task
[2022-02-08 01:35:01,203] {standard_task_runner.py:76} INFO - Running: ['***', 'tasks', 'run', 'Sample_one', 'save_csv', 'manual__2022-02-08T01:34:54.618638+00:00', '--job-id', '282', '--raw', '--subdir', 'DAGS_FOLDER/astradb.py', '--cfg-path', '/tmp/tmp1o38_02b', '--error-file', '/tmp/tmpr0nittt2']
[2022-02-08 01:35:01,205] {standard_task_runner.py:77} INFO - Job 282: Subtask save_csv
[2022-02-08 01:35:01,274] {logging_mixin.py:109} INFO - Running <TaskInstance: Sample_one.save_csv manual__2022-02-08T01:34:54.618638+00:00 [running]> on host 6d571ddbde8b
[2022-02-08 01:35:01,337] {taskinstance.py:1426} INFO - Exporting the following env vars:
AIRFLOW_CTX_DAG_OWNER=vathana
AIRFLOW_CTX_DAG_ID=Sample_one
AIRFLOW_CTX_TASK_ID=save_csv
AIRFLOW_CTX_EXECUTION_DATE=2022-02-08T01:34:54.618638+00:00
AIRFLOW_CTX_DAG_RUN_ID=manual__2022-02-08T01:34:54.618638+00:00
[2022-02-08 01:35:01,340] {subprocess.py:62} INFO - Tmp dir root location: 
 /tmp
[2022-02-08 01:35:01,341] {subprocess.py:74} INFO - Running command: ['bash', '-c', 'python3 /Users/vathanahim/Documents/GradSchool/capstone/689_Final_Project/***_folder/dags/connect.py']
[2022-02-08 01:35:01,359] {subprocess.py:85} INFO - Output:
[2022-02-08 01:35:01,475] {subprocess.py:89} INFO - python3: can't open file '/Users/vathanahim/Documents/GradSchool/capstone/689_Final_Project/***_folder/dags/connect.py': [Errno 2] No such file or directory
[2022-02-08 01:35:01,479] {subprocess.py:93} INFO - Command exited with return code 2
[2022-02-08 01:35:01,498] {taskinstance.py:1700} ERROR - Task failed with exception
Traceback (most recent call last):
  File "/home/airflow/.local/lib/python3.7/site-packages/airflow/models/taskinstance.py", line 1329, in _run_raw_task
    self._execute_task_with_callbacks(context)
  File "/home/airflow/.local/lib/python3.7/site-packages/airflow/models/taskinstance.py", line 1455, in _execute_task_with_callbacks
    result = self._execute_task(context, self.task)
  File "/home/airflow/.local/lib/python3.7/site-packages/airflow/models/taskinstance.py", line 1511, in _execute_task
    result = execute_callable(context=context)
  File "/home/airflow/.local/lib/python3.7/site-packages/airflow/operators/bash.py", line 188, in execute
    f'Bash command failed. The command returned a non-zero exit code {result.exit_code}.'
airflow.exceptions.AirflowException: Bash command failed. The command returned a non-zero exit code 2.
[2022-02-08 01:35:01,512] {taskinstance.py:1277} INFO - Marking task as FAILED. dag_id=Sample_one, task_id=save_csv, execution_date=20220208T013454, start_date=20220208T013501, end_date=20220208T013501
[2022-02-08 01:35:01,552] {standard_task_runner.py:92} ERROR - Failed to execute job 282 for task save_csv
Traceback (most recent call last):
  File "/home/airflow/.local/lib/python3.7/site-packages/airflow/task/task_runner/standard_task_runner.py", line 85, in _start_by_fork
    args.func(args, dag=self.dag)
  File "/home/airflow/.local/lib/python3.7/site-packages/airflow/cli/cli_parser.py", line 48, in command
    return func(*args, **kwargs)
  File "/home/airflow/.local/lib/python3.7/site-packages/airflow/utils/cli.py", line 92, in wrapper
    return f(*args, **kwargs)
  File "/home/airflow/.local/lib/python3.7/site-packages/airflow/cli/commands/task_command.py", line 298, in task_run
    _run_task_by_selected_method(args, dag, ti)
  File "/home/airflow/.local/lib/python3.7/site-packages/airflow/cli/commands/task_command.py", line 107, in _run_task_by_selected_method
    _run_raw_task(args, ti)
  File "/home/airflow/.local/lib/python3.7/site-packages/airflow/cli/commands/task_command.py", line 184, in _run_raw_task
    error_file=args.error_file,
  File "/home/airflow/.local/lib/python3.7/site-packages/airflow/utils/session.py", line 70, in wrapper
    return func(*args, session=session, **kwargs)
  File "/home/airflow/.local/lib/python3.7/site-packages/airflow/models/taskinstance.py", line 1329, in _run_raw_task
    self._execute_task_with_callbacks(context)
  File "/home/airflow/.local/lib/python3.7/site-packages/airflow/models/taskinstance.py", line 1455, in _execute_task_with_callbacks
    result = self._execute_task(context, self.task)
  File "/home/airflow/.local/lib/python3.7/site-packages/airflow/models/taskinstance.py", line 1511, in _execute_task
    result = execute_callable(context=context)
  File "/home/airflow/.local/lib/python3.7/site-packages/airflow/operators/bash.py", line 188, in execute
    f'Bash command failed. The command returned a non-zero exit code {result.exit_code}.'
airflow.exceptions.AirflowException: Bash command failed. The command returned a non-zero exit code 2.
[2022-02-08 01:35:01,578] {local_task_job.py:154} INFO - Task exited with return code 1
[2022-02-08 01:35:01,618] {local_task_job.py:264} INFO - 0 downstream tasks scheduled from follow-on schedule check
