[2022-02-04 01:53:41,298] {taskinstance.py:1032} INFO - Dependencies all met for <TaskInstance: Sample_one.connect_to_astra_db manual__2022-02-04T01:53:39.221909+00:00 [queued]>
[2022-02-04 01:53:41,311] {taskinstance.py:1032} INFO - Dependencies all met for <TaskInstance: Sample_one.connect_to_astra_db manual__2022-02-04T01:53:39.221909+00:00 [queued]>
[2022-02-04 01:53:41,313] {taskinstance.py:1238} INFO - 
--------------------------------------------------------------------------------
[2022-02-04 01:53:41,314] {taskinstance.py:1239} INFO - Starting attempt 1 of 1
[2022-02-04 01:53:41,317] {taskinstance.py:1240} INFO - 
--------------------------------------------------------------------------------
[2022-02-04 01:53:41,335] {taskinstance.py:1259} INFO - Executing <Task(BashOperator): connect_to_astra_db> on 2022-02-04 01:53:39.221909+00:00
[2022-02-04 01:53:41,345] {standard_task_runner.py:52} INFO - Started process 907 to run task
[2022-02-04 01:53:41,349] {standard_task_runner.py:76} INFO - Running: ['***', 'tasks', 'run', 'Sample_one', 'connect_to_astra_db', 'manual__2022-02-04T01:53:39.221909+00:00', '--job-id', '90', '--raw', '--subdir', 'DAGS_FOLDER/astradb.py', '--cfg-path', '/tmp/tmpkbfgljn6', '--error-file', '/tmp/tmpatx0upb7']
[2022-02-04 01:53:41,352] {standard_task_runner.py:77} INFO - Job 90: Subtask connect_to_astra_db
[2022-02-04 01:53:41,484] {logging_mixin.py:109} INFO - Running <TaskInstance: Sample_one.connect_to_astra_db manual__2022-02-04T01:53:39.221909+00:00 [running]> on host 8c7de8c21c73
[2022-02-04 01:53:41,546] {taskinstance.py:1426} INFO - Exporting the following env vars:
AIRFLOW_CTX_DAG_OWNER=vathana
AIRFLOW_CTX_DAG_ID=Sample_one
AIRFLOW_CTX_TASK_ID=connect_to_astra_db
AIRFLOW_CTX_EXECUTION_DATE=2022-02-04T01:53:39.221909+00:00
AIRFLOW_CTX_DAG_RUN_ID=manual__2022-02-04T01:53:39.221909+00:00
[2022-02-04 01:53:41,550] {subprocess.py:62} INFO - Tmp dir root location: 
 /tmp
[2022-02-04 01:53:41,553] {subprocess.py:74} INFO - Running command: ['bash', '-c', 'python /dags/connect.py']
[2022-02-04 01:53:41,582] {subprocess.py:85} INFO - Output:
[2022-02-04 01:53:41,728] {subprocess.py:89} INFO - python: can't open file '/dags/connect.py': [Errno 2] No such file or directory
[2022-02-04 01:53:41,733] {subprocess.py:93} INFO - Command exited with return code 2
[2022-02-04 01:53:41,753] {taskinstance.py:1700} ERROR - Task failed with exception
Traceback (most recent call last):
  File "/home/airflow/.local/lib/python3.7/site-packages/airflow/models/taskinstance.py", line 1329, in _run_raw_task
    self._execute_task_with_callbacks(context)
  File "/home/airflow/.local/lib/python3.7/site-packages/airflow/models/taskinstance.py", line 1455, in _execute_task_with_callbacks
    result = self._execute_task(context, self.task)
  File "/home/airflow/.local/lib/python3.7/site-packages/airflow/models/taskinstance.py", line 1511, in _execute_task
    result = execute_callable(context=context)
  File "/home/airflow/.local/lib/python3.7/site-packages/airflow/operators/bash.py", line 188, in execute
    f'Bash command failed. The command returned a non-zero exit code {result.exit_code}.'
airflow.exceptions.AirflowException: Bash command failed. The command returned a non-zero exit code 2.
[2022-02-04 01:53:41,767] {taskinstance.py:1277} INFO - Marking task as FAILED. dag_id=Sample_one, task_id=connect_to_astra_db, execution_date=20220204T015339, start_date=20220204T015341, end_date=20220204T015341
[2022-02-04 01:53:41,789] {standard_task_runner.py:92} ERROR - Failed to execute job 90 for task connect_to_astra_db
Traceback (most recent call last):
  File "/home/airflow/.local/lib/python3.7/site-packages/airflow/task/task_runner/standard_task_runner.py", line 85, in _start_by_fork
    args.func(args, dag=self.dag)
  File "/home/airflow/.local/lib/python3.7/site-packages/airflow/cli/cli_parser.py", line 48, in command
    return func(*args, **kwargs)
  File "/home/airflow/.local/lib/python3.7/site-packages/airflow/utils/cli.py", line 92, in wrapper
    return f(*args, **kwargs)
  File "/home/airflow/.local/lib/python3.7/site-packages/airflow/cli/commands/task_command.py", line 298, in task_run
    _run_task_by_selected_method(args, dag, ti)
  File "/home/airflow/.local/lib/python3.7/site-packages/airflow/cli/commands/task_command.py", line 107, in _run_task_by_selected_method
    _run_raw_task(args, ti)
  File "/home/airflow/.local/lib/python3.7/site-packages/airflow/cli/commands/task_command.py", line 184, in _run_raw_task
    error_file=args.error_file,
  File "/home/airflow/.local/lib/python3.7/site-packages/airflow/utils/session.py", line 70, in wrapper
    return func(*args, session=session, **kwargs)
  File "/home/airflow/.local/lib/python3.7/site-packages/airflow/models/taskinstance.py", line 1329, in _run_raw_task
    self._execute_task_with_callbacks(context)
  File "/home/airflow/.local/lib/python3.7/site-packages/airflow/models/taskinstance.py", line 1455, in _execute_task_with_callbacks
    result = self._execute_task(context, self.task)
  File "/home/airflow/.local/lib/python3.7/site-packages/airflow/models/taskinstance.py", line 1511, in _execute_task
    result = execute_callable(context=context)
  File "/home/airflow/.local/lib/python3.7/site-packages/airflow/operators/bash.py", line 188, in execute
    f'Bash command failed. The command returned a non-zero exit code {result.exit_code}.'
airflow.exceptions.AirflowException: Bash command failed. The command returned a non-zero exit code 2.
[2022-02-04 01:53:41,849] {local_task_job.py:154} INFO - Task exited with return code 1
[2022-02-04 01:53:41,925] {local_task_job.py:264} INFO - 0 downstream tasks scheduled from follow-on schedule check
