[2022-03-03 15:31:01,017] {taskinstance.py:1032} INFO - Dependencies all met for <TaskInstance: Sample_one.process_kmeans manual__2022-03-03T15:30:58.097776+00:00 [queued]>
[2022-03-03 15:31:01,030] {taskinstance.py:1032} INFO - Dependencies all met for <TaskInstance: Sample_one.process_kmeans manual__2022-03-03T15:30:58.097776+00:00 [queued]>
[2022-03-03 15:31:01,032] {taskinstance.py:1238} INFO - 
--------------------------------------------------------------------------------
[2022-03-03 15:31:01,032] {taskinstance.py:1239} INFO - Starting attempt 1 of 1
[2022-03-03 15:31:01,033] {taskinstance.py:1240} INFO - 
--------------------------------------------------------------------------------
[2022-03-03 15:31:01,046] {taskinstance.py:1259} INFO - Executing <Task(PythonOperator): process_kmeans> on 2022-03-03 15:30:58.097776+00:00
[2022-03-03 15:31:01,053] {standard_task_runner.py:52} INFO - Started process 559 to run task
[2022-03-03 15:31:01,059] {standard_task_runner.py:76} INFO - Running: ['***', 'tasks', 'run', 'Sample_one', 'process_kmeans', 'manual__2022-03-03T15:30:58.097776+00:00', '--job-id', '81', '--raw', '--subdir', 'DAGS_FOLDER/dag.py', '--cfg-path', '/tmp/tmpw_w1p_aq', '--error-file', '/tmp/tmprd8hwlvc']
[2022-03-03 15:31:01,061] {standard_task_runner.py:77} INFO - Job 81: Subtask process_kmeans
[2022-03-03 15:31:01,118] {logging_mixin.py:109} INFO - Running <TaskInstance: Sample_one.process_kmeans manual__2022-03-03T15:30:58.097776+00:00 [running]> on host 99813ca71bd1
[2022-03-03 15:31:01,188] {taskinstance.py:1426} INFO - Exporting the following env vars:
AIRFLOW_CTX_DAG_OWNER=vathana
AIRFLOW_CTX_DAG_ID=Sample_one
AIRFLOW_CTX_TASK_ID=process_kmeans
AIRFLOW_CTX_EXECUTION_DATE=2022-03-03T15:30:58.097776+00:00
AIRFLOW_CTX_DAG_RUN_ID=manual__2022-03-03T15:30:58.097776+00:00
[2022-03-03 15:31:07,085] {__init__.py:140} ERROR - <urlopen error _ssl.c:1074: The handshake operation timed out>
Traceback (most recent call last):
  File "/usr/local/lib/python3.7/urllib/request.py", line 1350, in do_open
    encode_chunked=req.has_header('Transfer-encoding'))
  File "/usr/local/lib/python3.7/http/client.py", line 1281, in request
    self._send_request(method, url, body, headers, encode_chunked)
  File "/usr/local/lib/python3.7/http/client.py", line 1327, in _send_request
    self.endheaders(body, encode_chunked=encode_chunked)
  File "/usr/local/lib/python3.7/http/client.py", line 1276, in endheaders
    self._send_output(message_body, encode_chunked=encode_chunked)
  File "/usr/local/lib/python3.7/http/client.py", line 1036, in _send_output
    self.send(msg)
  File "/usr/local/lib/python3.7/http/client.py", line 976, in send
    self.connect()
  File "/usr/local/lib/python3.7/http/client.py", line 1451, in connect
    server_hostname=server_hostname)
  File "/usr/local/lib/python3.7/ssl.py", line 423, in wrap_socket
    session=session
  File "/usr/local/lib/python3.7/ssl.py", line 870, in _create
    self.do_handshake()
  File "/usr/local/lib/python3.7/ssl.py", line 1139, in do_handshake
    self._sslobj.do_handshake()
socket.timeout: _ssl.c:1074: The handshake operation timed out

During handling of the above exception, another exception occurred:

Traceback (most recent call last):
  File "/home/airflow/.local/lib/python3.7/site-packages/cassandra/datastax/cloud/__init__.py", line 138, in read_metadata_info
    response = urlopen(url, context=config.ssl_context, timeout=timeout)
  File "/usr/local/lib/python3.7/urllib/request.py", line 222, in urlopen
    return opener.open(url, data, timeout)
  File "/usr/local/lib/python3.7/urllib/request.py", line 525, in open
    response = self._open(req, data)
  File "/usr/local/lib/python3.7/urllib/request.py", line 543, in _open
    '_open', req)
  File "/usr/local/lib/python3.7/urllib/request.py", line 503, in _call_chain
    result = func(*args)
  File "/usr/local/lib/python3.7/urllib/request.py", line 1393, in https_open
    context=self._context, check_hostname=self._check_hostname)
  File "/usr/local/lib/python3.7/urllib/request.py", line 1352, in do_open
    raise URLError(err)
urllib.error.URLError: <urlopen error _ssl.c:1074: The handshake operation timed out>
[2022-03-03 15:31:07,088] {taskinstance.py:1700} ERROR - Task failed with exception
Traceback (most recent call last):
  File "/usr/local/lib/python3.7/urllib/request.py", line 1350, in do_open
    encode_chunked=req.has_header('Transfer-encoding'))
  File "/usr/local/lib/python3.7/http/client.py", line 1281, in request
    self._send_request(method, url, body, headers, encode_chunked)
  File "/usr/local/lib/python3.7/http/client.py", line 1327, in _send_request
    self.endheaders(body, encode_chunked=encode_chunked)
  File "/usr/local/lib/python3.7/http/client.py", line 1276, in endheaders
    self._send_output(message_body, encode_chunked=encode_chunked)
  File "/usr/local/lib/python3.7/http/client.py", line 1036, in _send_output
    self.send(msg)
  File "/usr/local/lib/python3.7/http/client.py", line 976, in send
    self.connect()
  File "/usr/local/lib/python3.7/http/client.py", line 1451, in connect
    server_hostname=server_hostname)
  File "/usr/local/lib/python3.7/ssl.py", line 423, in wrap_socket
    session=session
  File "/usr/local/lib/python3.7/ssl.py", line 870, in _create
    self.do_handshake()
  File "/usr/local/lib/python3.7/ssl.py", line 1139, in do_handshake
    self._sslobj.do_handshake()
socket.timeout: _ssl.c:1074: The handshake operation timed out

During handling of the above exception, another exception occurred:

Traceback (most recent call last):
  File "/home/airflow/.local/lib/python3.7/site-packages/cassandra/datastax/cloud/__init__.py", line 138, in read_metadata_info
    response = urlopen(url, context=config.ssl_context, timeout=timeout)
  File "/usr/local/lib/python3.7/urllib/request.py", line 222, in urlopen
    return opener.open(url, data, timeout)
  File "/usr/local/lib/python3.7/urllib/request.py", line 525, in open
    response = self._open(req, data)
  File "/usr/local/lib/python3.7/urllib/request.py", line 543, in _open
    '_open', req)
  File "/usr/local/lib/python3.7/urllib/request.py", line 503, in _call_chain
    result = func(*args)
  File "/usr/local/lib/python3.7/urllib/request.py", line 1393, in https_open
    context=self._context, check_hostname=self._check_hostname)
  File "/usr/local/lib/python3.7/urllib/request.py", line 1352, in do_open
    raise URLError(err)
urllib.error.URLError: <urlopen error _ssl.c:1074: The handshake operation timed out>

During handling of the above exception, another exception occurred:

Traceback (most recent call last):
  File "/home/airflow/.local/lib/python3.7/site-packages/airflow/models/taskinstance.py", line 1329, in _run_raw_task
    self._execute_task_with_callbacks(context)
  File "/home/airflow/.local/lib/python3.7/site-packages/airflow/models/taskinstance.py", line 1455, in _execute_task_with_callbacks
    result = self._execute_task(context, self.task)
  File "/home/airflow/.local/lib/python3.7/site-packages/airflow/models/taskinstance.py", line 1511, in _execute_task
    result = execute_callable(context=context)
  File "/home/airflow/.local/lib/python3.7/site-packages/airflow/operators/python.py", line 174, in execute
    return_value = self.execute_callable()
  File "/home/airflow/.local/lib/python3.7/site-packages/airflow/operators/python.py", line 185, in execute_callable
    return self.python_callable(*self.op_args, **self.op_kwargs)
  File "/opt/airflow/dags/dag.py", line 26, in kmeans
    cluster = Cluster(cloud=cloud_config, auth_provider=auth_provider)
  File "cassandra/cluster.py", line 1125, in cassandra.cluster.Cluster.__init__
  File "/home/airflow/.local/lib/python3.7/site-packages/cassandra/datastax/cloud/__init__.py", line 92, in get_cloud_config
    config = read_metadata_info(config, cloud_config)
  File "/home/airflow/.local/lib/python3.7/site-packages/cassandra/datastax/cloud/__init__.py", line 142, in read_metadata_info
    "Check the cluster status in the cloud console. " % url)
cassandra.DriverException: Unable to connect to the metadata service at https://3844b209-e6f1-4eda-8605-b019293c1e08-us-east1.db.astra.datastax.com:29080/metadata. Check the cluster status in the cloud console. 
[2022-03-03 15:31:07,106] {taskinstance.py:1277} INFO - Marking task as FAILED. dag_id=Sample_one, task_id=process_kmeans, execution_date=20220303T153058, start_date=20220303T153101, end_date=20220303T153107
[2022-03-03 15:31:07,128] {standard_task_runner.py:92} ERROR - Failed to execute job 81 for task process_kmeans
Traceback (most recent call last):
  File "/usr/local/lib/python3.7/urllib/request.py", line 1350, in do_open
    encode_chunked=req.has_header('Transfer-encoding'))
  File "/usr/local/lib/python3.7/http/client.py", line 1281, in request
    self._send_request(method, url, body, headers, encode_chunked)
  File "/usr/local/lib/python3.7/http/client.py", line 1327, in _send_request
    self.endheaders(body, encode_chunked=encode_chunked)
  File "/usr/local/lib/python3.7/http/client.py", line 1276, in endheaders
    self._send_output(message_body, encode_chunked=encode_chunked)
  File "/usr/local/lib/python3.7/http/client.py", line 1036, in _send_output
    self.send(msg)
  File "/usr/local/lib/python3.7/http/client.py", line 976, in send
    self.connect()
  File "/usr/local/lib/python3.7/http/client.py", line 1451, in connect
    server_hostname=server_hostname)
  File "/usr/local/lib/python3.7/ssl.py", line 423, in wrap_socket
    session=session
  File "/usr/local/lib/python3.7/ssl.py", line 870, in _create
    self.do_handshake()
  File "/usr/local/lib/python3.7/ssl.py", line 1139, in do_handshake
    self._sslobj.do_handshake()
socket.timeout: _ssl.c:1074: The handshake operation timed out

During handling of the above exception, another exception occurred:

Traceback (most recent call last):
  File "/home/airflow/.local/lib/python3.7/site-packages/cassandra/datastax/cloud/__init__.py", line 138, in read_metadata_info
    response = urlopen(url, context=config.ssl_context, timeout=timeout)
  File "/usr/local/lib/python3.7/urllib/request.py", line 222, in urlopen
    return opener.open(url, data, timeout)
  File "/usr/local/lib/python3.7/urllib/request.py", line 525, in open
    response = self._open(req, data)
  File "/usr/local/lib/python3.7/urllib/request.py", line 543, in _open
    '_open', req)
  File "/usr/local/lib/python3.7/urllib/request.py", line 503, in _call_chain
    result = func(*args)
  File "/usr/local/lib/python3.7/urllib/request.py", line 1393, in https_open
    context=self._context, check_hostname=self._check_hostname)
  File "/usr/local/lib/python3.7/urllib/request.py", line 1352, in do_open
    raise URLError(err)
urllib.error.URLError: <urlopen error _ssl.c:1074: The handshake operation timed out>

During handling of the above exception, another exception occurred:

Traceback (most recent call last):
  File "/home/airflow/.local/lib/python3.7/site-packages/airflow/task/task_runner/standard_task_runner.py", line 85, in _start_by_fork
    args.func(args, dag=self.dag)
  File "/home/airflow/.local/lib/python3.7/site-packages/airflow/cli/cli_parser.py", line 48, in command
    return func(*args, **kwargs)
  File "/home/airflow/.local/lib/python3.7/site-packages/airflow/utils/cli.py", line 92, in wrapper
    return f(*args, **kwargs)
  File "/home/airflow/.local/lib/python3.7/site-packages/airflow/cli/commands/task_command.py", line 298, in task_run
    _run_task_by_selected_method(args, dag, ti)
  File "/home/airflow/.local/lib/python3.7/site-packages/airflow/cli/commands/task_command.py", line 107, in _run_task_by_selected_method
    _run_raw_task(args, ti)
  File "/home/airflow/.local/lib/python3.7/site-packages/airflow/cli/commands/task_command.py", line 184, in _run_raw_task
    error_file=args.error_file,
  File "/home/airflow/.local/lib/python3.7/site-packages/airflow/utils/session.py", line 70, in wrapper
    return func(*args, session=session, **kwargs)
  File "/home/airflow/.local/lib/python3.7/site-packages/airflow/models/taskinstance.py", line 1329, in _run_raw_task
    self._execute_task_with_callbacks(context)
  File "/home/airflow/.local/lib/python3.7/site-packages/airflow/models/taskinstance.py", line 1455, in _execute_task_with_callbacks
    result = self._execute_task(context, self.task)
  File "/home/airflow/.local/lib/python3.7/site-packages/airflow/models/taskinstance.py", line 1511, in _execute_task
    result = execute_callable(context=context)
  File "/home/airflow/.local/lib/python3.7/site-packages/airflow/operators/python.py", line 174, in execute
    return_value = self.execute_callable()
  File "/home/airflow/.local/lib/python3.7/site-packages/airflow/operators/python.py", line 185, in execute_callable
    return self.python_callable(*self.op_args, **self.op_kwargs)
  File "/opt/airflow/dags/dag.py", line 26, in kmeans
    cluster = Cluster(cloud=cloud_config, auth_provider=auth_provider)
  File "cassandra/cluster.py", line 1125, in cassandra.cluster.Cluster.__init__
  File "/home/airflow/.local/lib/python3.7/site-packages/cassandra/datastax/cloud/__init__.py", line 92, in get_cloud_config
    config = read_metadata_info(config, cloud_config)
  File "/home/airflow/.local/lib/python3.7/site-packages/cassandra/datastax/cloud/__init__.py", line 142, in read_metadata_info
    "Check the cluster status in the cloud console. " % url)
cassandra.DriverException: Unable to connect to the metadata service at https://3844b209-e6f1-4eda-8605-b019293c1e08-us-east1.db.astra.datastax.com:29080/metadata. Check the cluster status in the cloud console. 
[2022-03-03 15:31:07,167] {local_task_job.py:154} INFO - Task exited with return code 1
[2022-03-03 15:31:07,216] {local_task_job.py:264} INFO - 0 downstream tasks scheduled from follow-on schedule check
