[2022-02-04 01:21:30,863] {taskinstance.py:1032} INFO - Dependencies all met for <TaskInstance: Sample_one.connect_to_astra_db manual__2022-02-04T01:21:27.736519+00:00 [queued]>
[2022-02-04 01:21:30,873] {taskinstance.py:1032} INFO - Dependencies all met for <TaskInstance: Sample_one.connect_to_astra_db manual__2022-02-04T01:21:27.736519+00:00 [queued]>
[2022-02-04 01:21:30,875] {taskinstance.py:1238} INFO - 
--------------------------------------------------------------------------------
[2022-02-04 01:21:30,876] {taskinstance.py:1239} INFO - Starting attempt 1 of 1
[2022-02-04 01:21:30,877] {taskinstance.py:1240} INFO - 
--------------------------------------------------------------------------------
[2022-02-04 01:21:30,891] {taskinstance.py:1259} INFO - Executing <Task(PythonOperator): connect_to_astra_db> on 2022-02-04 01:21:27.736519+00:00
[2022-02-04 01:21:30,900] {standard_task_runner.py:52} INFO - Started process 283 to run task
[2022-02-04 01:21:30,907] {standard_task_runner.py:76} INFO - Running: ['***', 'tasks', 'run', 'Sample_one', 'connect_to_astra_db', 'manual__2022-02-04T01:21:27.736519+00:00', '--job-id', '52', '--raw', '--subdir', 'DAGS_FOLDER/astradb.py', '--cfg-path', '/tmp/tmp4g2sqtas', '--error-file', '/tmp/tmpnxbq3tks']
[2022-02-04 01:21:30,919] {standard_task_runner.py:77} INFO - Job 52: Subtask connect_to_astra_db
[2022-02-04 01:21:31,028] {logging_mixin.py:109} INFO - Running <TaskInstance: Sample_one.connect_to_astra_db manual__2022-02-04T01:21:27.736519+00:00 [running]> on host 8c7de8c21c73
[2022-02-04 01:21:31,084] {taskinstance.py:1426} INFO - Exporting the following env vars:
AIRFLOW_CTX_DAG_OWNER=vathana
AIRFLOW_CTX_DAG_ID=Sample_one
AIRFLOW_CTX_TASK_ID=connect_to_astra_db
AIRFLOW_CTX_EXECUTION_DATE=2022-02-04T01:21:27.736519+00:00
AIRFLOW_CTX_DAG_RUN_ID=manual__2022-02-04T01:21:27.736519+00:00
[2022-02-04 01:21:33,398] {__init__.py:140} ERROR - HTTP Error 503: Service Unavailable
Traceback (most recent call last):
  File "/home/airflow/.local/lib/python3.7/site-packages/cassandra/datastax/cloud/__init__.py", line 138, in read_metadata_info
    response = urlopen(url, context=config.ssl_context, timeout=timeout)
  File "/usr/local/lib/python3.7/urllib/request.py", line 222, in urlopen
    return opener.open(url, data, timeout)
  File "/usr/local/lib/python3.7/urllib/request.py", line 531, in open
    response = meth(req, response)
  File "/usr/local/lib/python3.7/urllib/request.py", line 641, in http_response
    'http', request, response, code, msg, hdrs)
  File "/usr/local/lib/python3.7/urllib/request.py", line 569, in error
    return self._call_chain(*args)
  File "/usr/local/lib/python3.7/urllib/request.py", line 503, in _call_chain
    result = func(*args)
  File "/usr/local/lib/python3.7/urllib/request.py", line 649, in http_error_default
    raise HTTPError(req.full_url, code, msg, hdrs, fp)
urllib.error.HTTPError: HTTP Error 503: Service Unavailable
[2022-02-04 01:21:33,402] {taskinstance.py:1700} ERROR - Task failed with exception
Traceback (most recent call last):
  File "/home/airflow/.local/lib/python3.7/site-packages/cassandra/datastax/cloud/__init__.py", line 138, in read_metadata_info
    response = urlopen(url, context=config.ssl_context, timeout=timeout)
  File "/usr/local/lib/python3.7/urllib/request.py", line 222, in urlopen
    return opener.open(url, data, timeout)
  File "/usr/local/lib/python3.7/urllib/request.py", line 531, in open
    response = meth(req, response)
  File "/usr/local/lib/python3.7/urllib/request.py", line 641, in http_response
    'http', request, response, code, msg, hdrs)
  File "/usr/local/lib/python3.7/urllib/request.py", line 569, in error
    return self._call_chain(*args)
  File "/usr/local/lib/python3.7/urllib/request.py", line 503, in _call_chain
    result = func(*args)
  File "/usr/local/lib/python3.7/urllib/request.py", line 649, in http_error_default
    raise HTTPError(req.full_url, code, msg, hdrs, fp)
urllib.error.HTTPError: HTTP Error 503: Service Unavailable

During handling of the above exception, another exception occurred:

Traceback (most recent call last):
  File "/home/airflow/.local/lib/python3.7/site-packages/airflow/models/taskinstance.py", line 1329, in _run_raw_task
    self._execute_task_with_callbacks(context)
  File "/home/airflow/.local/lib/python3.7/site-packages/airflow/models/taskinstance.py", line 1455, in _execute_task_with_callbacks
    result = self._execute_task(context, self.task)
  File "/home/airflow/.local/lib/python3.7/site-packages/airflow/models/taskinstance.py", line 1511, in _execute_task
    result = execute_callable(context=context)
  File "/home/airflow/.local/lib/python3.7/site-packages/airflow/operators/python.py", line 174, in execute
    return_value = self.execute_callable()
  File "/home/airflow/.local/lib/python3.7/site-packages/airflow/operators/python.py", line 185, in execute_callable
    return self.python_callable(*self.op_args, **self.op_kwargs)
  File "/opt/airflow/dags/astradb.py", line 22, in astra_connect
    cluster = Cluster(cloud=cloud_config, auth_provider=auth_provider)
  File "cassandra/cluster.py", line 1125, in cassandra.cluster.Cluster.__init__
  File "/home/airflow/.local/lib/python3.7/site-packages/cassandra/datastax/cloud/__init__.py", line 92, in get_cloud_config
    config = read_metadata_info(config, cloud_config)
  File "/home/airflow/.local/lib/python3.7/site-packages/cassandra/datastax/cloud/__init__.py", line 142, in read_metadata_info
    "Check the cluster status in the cloud console. " % url)
cassandra.DriverException: Unable to connect to the metadata service at https://3844b209-e6f1-4eda-8605-b019293c1e08-us-east1.db.astra.datastax.com:29080/metadata. Check the cluster status in the cloud console. 
[2022-02-04 01:21:33,429] {taskinstance.py:1277} INFO - Marking task as FAILED. dag_id=Sample_one, task_id=connect_to_astra_db, execution_date=20220204T012127, start_date=20220204T012130, end_date=20220204T012133
[2022-02-04 01:21:33,447] {standard_task_runner.py:92} ERROR - Failed to execute job 52 for task connect_to_astra_db
Traceback (most recent call last):
  File "/home/airflow/.local/lib/python3.7/site-packages/cassandra/datastax/cloud/__init__.py", line 138, in read_metadata_info
    response = urlopen(url, context=config.ssl_context, timeout=timeout)
  File "/usr/local/lib/python3.7/urllib/request.py", line 222, in urlopen
    return opener.open(url, data, timeout)
  File "/usr/local/lib/python3.7/urllib/request.py", line 531, in open
    response = meth(req, response)
  File "/usr/local/lib/python3.7/urllib/request.py", line 641, in http_response
    'http', request, response, code, msg, hdrs)
  File "/usr/local/lib/python3.7/urllib/request.py", line 569, in error
    return self._call_chain(*args)
  File "/usr/local/lib/python3.7/urllib/request.py", line 503, in _call_chain
    result = func(*args)
  File "/usr/local/lib/python3.7/urllib/request.py", line 649, in http_error_default
    raise HTTPError(req.full_url, code, msg, hdrs, fp)
urllib.error.HTTPError: HTTP Error 503: Service Unavailable

During handling of the above exception, another exception occurred:

Traceback (most recent call last):
  File "/home/airflow/.local/lib/python3.7/site-packages/airflow/task/task_runner/standard_task_runner.py", line 85, in _start_by_fork
    args.func(args, dag=self.dag)
  File "/home/airflow/.local/lib/python3.7/site-packages/airflow/cli/cli_parser.py", line 48, in command
    return func(*args, **kwargs)
  File "/home/airflow/.local/lib/python3.7/site-packages/airflow/utils/cli.py", line 92, in wrapper
    return f(*args, **kwargs)
  File "/home/airflow/.local/lib/python3.7/site-packages/airflow/cli/commands/task_command.py", line 298, in task_run
    _run_task_by_selected_method(args, dag, ti)
  File "/home/airflow/.local/lib/python3.7/site-packages/airflow/cli/commands/task_command.py", line 107, in _run_task_by_selected_method
    _run_raw_task(args, ti)
  File "/home/airflow/.local/lib/python3.7/site-packages/airflow/cli/commands/task_command.py", line 184, in _run_raw_task
    error_file=args.error_file,
  File "/home/airflow/.local/lib/python3.7/site-packages/airflow/utils/session.py", line 70, in wrapper
    return func(*args, session=session, **kwargs)
  File "/home/airflow/.local/lib/python3.7/site-packages/airflow/models/taskinstance.py", line 1329, in _run_raw_task
    self._execute_task_with_callbacks(context)
  File "/home/airflow/.local/lib/python3.7/site-packages/airflow/models/taskinstance.py", line 1455, in _execute_task_with_callbacks
    result = self._execute_task(context, self.task)
  File "/home/airflow/.local/lib/python3.7/site-packages/airflow/models/taskinstance.py", line 1511, in _execute_task
    result = execute_callable(context=context)
  File "/home/airflow/.local/lib/python3.7/site-packages/airflow/operators/python.py", line 174, in execute
    return_value = self.execute_callable()
  File "/home/airflow/.local/lib/python3.7/site-packages/airflow/operators/python.py", line 185, in execute_callable
    return self.python_callable(*self.op_args, **self.op_kwargs)
  File "/opt/airflow/dags/astradb.py", line 22, in astra_connect
    cluster = Cluster(cloud=cloud_config, auth_provider=auth_provider)
  File "cassandra/cluster.py", line 1125, in cassandra.cluster.Cluster.__init__
  File "/home/airflow/.local/lib/python3.7/site-packages/cassandra/datastax/cloud/__init__.py", line 92, in get_cloud_config
    config = read_metadata_info(config, cloud_config)
  File "/home/airflow/.local/lib/python3.7/site-packages/cassandra/datastax/cloud/__init__.py", line 142, in read_metadata_info
    "Check the cluster status in the cloud console. " % url)
cassandra.DriverException: Unable to connect to the metadata service at https://3844b209-e6f1-4eda-8605-b019293c1e08-us-east1.db.astra.datastax.com:29080/metadata. Check the cluster status in the cloud console. 
[2022-02-04 01:21:33,481] {local_task_job.py:154} INFO - Task exited with return code 1
[2022-02-04 01:21:33,587] {local_task_job.py:264} INFO - 0 downstream tasks scheduled from follow-on schedule check
